[2025-01-20T13:00:44.120+0000] {local_task_job_runner.py:123} INFO - ::group::Pre task execution logs
[2025-01-20T13:00:44.128+0000] {taskinstance.py:2613} INFO - Dependencies all met for dep_context=non-requeueable deps ti=<TaskInstance: connection_postgre.connection_to_db manual__2025-01-20T13:00:42.708236+00:00 [queued]>
[2025-01-20T13:00:44.133+0000] {taskinstance.py:2613} INFO - Dependencies all met for dep_context=requeueable deps ti=<TaskInstance: connection_postgre.connection_to_db manual__2025-01-20T13:00:42.708236+00:00 [queued]>
[2025-01-20T13:00:44.133+0000] {taskinstance.py:2866} INFO - Starting attempt 1 of 1
[2025-01-20T13:00:44.143+0000] {taskinstance.py:2889} INFO - Executing <Task(PythonOperator): connection_to_db> on 2025-01-20 13:00:42.708236+00:00
[2025-01-20T13:00:44.149+0000] {warnings.py:112} WARNING - /home/***/.local/lib/python3.12/site-packages/***/task/task_runner/standard_task_runner.py:70: DeprecationWarning: This process (pid=1692) is multi-threaded, use of fork() may lead to deadlocks in the child.
  pid = os.fork()

[2025-01-20T13:00:44.151+0000] {standard_task_runner.py:72} INFO - Started process 1694 to run task
[2025-01-20T13:00:44.150+0000] {standard_task_runner.py:104} INFO - Running: ['***', 'tasks', 'run', 'connection_postgre', 'connection_to_db', 'manual__2025-01-20T13:00:42.708236+00:00', '--job-id', '151', '--raw', '--subdir', 'DAGS_FOLDER/postgre.py', '--cfg-path', '/tmp/tmp1m_u7o8u']
[2025-01-20T13:00:44.152+0000] {standard_task_runner.py:105} INFO - Job 151: Subtask connection_to_db
[2025-01-20T13:00:44.188+0000] {task_command.py:467} INFO - Running <TaskInstance: connection_postgre.connection_to_db manual__2025-01-20T13:00:42.708236+00:00 [running]> on host 7854821b9569
[2025-01-20T13:00:44.354+0000] {taskinstance.py:3132} INFO - Exporting env vars: AIRFLOW_CTX_DAG_OWNER='***' AIRFLOW_CTX_DAG_ID='connection_postgre' AIRFLOW_CTX_TASK_ID='connection_to_db' AIRFLOW_CTX_EXECUTION_DATE='2025-01-20T13:00:42.708236+00:00' AIRFLOW_CTX_TRY_NUMBER='1' AIRFLOW_CTX_DAG_RUN_ID='manual__2025-01-20T13:00:42.708236+00:00'
[2025-01-20T13:00:44.355+0000] {taskinstance.py:731} INFO - ::endgroup::
[2025-01-20T13:00:44.373+0000] {base.py:84} INFO - Retrieving connection 'postgres_connexion'
[2025-01-20T13:00:44.757+0000] {taskinstance.py:3311} ERROR - Task failed with exception
Traceback (most recent call last):
  File "/home/airflow/.local/lib/python3.12/site-packages/airflow/models/taskinstance.py", line 767, in _execute_task
    result = _execute_callable(context=context, **execute_callable_kwargs)
             ^^^^^^^^^^^^^^^^^^^^^^^^^^^^^^^^^^^^^^^^^^^^^^^^^^^^^^^^^^^^^
  File "/home/airflow/.local/lib/python3.12/site-packages/airflow/models/taskinstance.py", line 733, in _execute_callable
    return ExecutionCallableRunner(
           ^^^^^^^^^^^^^^^^^^^^^^^^
  File "/home/airflow/.local/lib/python3.12/site-packages/airflow/utils/operator_helpers.py", line 252, in run
    return self.func(*args, **kwargs)
           ^^^^^^^^^^^^^^^^^^^^^^^^^^
  File "/home/airflow/.local/lib/python3.12/site-packages/airflow/models/baseoperator.py", line 422, in wrapper
    return func(self, *args, **kwargs)
           ^^^^^^^^^^^^^^^^^^^^^^^^^^^
  File "/home/airflow/.local/lib/python3.12/site-packages/airflow/operators/python.py", line 238, in execute
    return_value = self.execute_callable()
                   ^^^^^^^^^^^^^^^^^^^^^^^
  File "/home/airflow/.local/lib/python3.12/site-packages/airflow/operators/python.py", line 256, in execute_callable
    return runner.run(*self.op_args, **self.op_kwargs)
           ^^^^^^^^^^^^^^^^^^^^^^^^^^^^^^^^^^^^^^^^^^^
  File "/home/airflow/.local/lib/python3.12/site-packages/airflow/utils/operator_helpers.py", line 252, in run
    return self.func(*args, **kwargs)
           ^^^^^^^^^^^^^^^^^^^^^^^^^^
  File "/opt/airflow/dags/postgre.py", line 13, in get_data
    cols=[desc[0] for desc in cursor.description()]
                              ^^^^^^^^^^^^^^^^^^^^
TypeError: 'tuple' object is not callable
[2025-01-20T13:00:44.768+0000] {taskinstance.py:1225} INFO - Marking task as FAILED. dag_id=connection_postgre, task_id=connection_to_db, run_id=manual__2025-01-20T13:00:42.708236+00:00, execution_date=20250120T130042, start_date=20250120T130044, end_date=20250120T130044
[2025-01-20T13:00:44.777+0000] {taskinstance.py:340} INFO - ::group::Post task execution logs
[2025-01-20T13:00:44.777+0000] {standard_task_runner.py:124} ERROR - Failed to execute job 151 for task connection_to_db ('tuple' object is not callable; 1694)
Traceback (most recent call last):
  File "/home/airflow/.local/lib/python3.12/site-packages/airflow/task/task_runner/standard_task_runner.py", line 117, in _start_by_fork
    ret = args.func(args, dag=self.dag)
          ^^^^^^^^^^^^^^^^^^^^^^^^^^^^^
  File "/home/airflow/.local/lib/python3.12/site-packages/airflow/cli/cli_config.py", line 49, in command
    return func(*args, **kwargs)
           ^^^^^^^^^^^^^^^^^^^^^
  File "/home/airflow/.local/lib/python3.12/site-packages/airflow/utils/cli.py", line 116, in wrapper
    return f(*args, **kwargs)
           ^^^^^^^^^^^^^^^^^^
  File "/home/airflow/.local/lib/python3.12/site-packages/airflow/cli/commands/task_command.py", line 483, in task_run
    task_return_code = _run_task_by_selected_method(args, _dag, ti)
                       ^^^^^^^^^^^^^^^^^^^^^^^^^^^^^^^^^^^^^^^^^^^^
  File "/home/airflow/.local/lib/python3.12/site-packages/airflow/cli/commands/task_command.py", line 256, in _run_task_by_selected_method
    return _run_raw_task(args, ti)
           ^^^^^^^^^^^^^^^^^^^^^^^
  File "/home/airflow/.local/lib/python3.12/site-packages/airflow/cli/commands/task_command.py", line 341, in _run_raw_task
    return ti._run_raw_task(
           ^^^^^^^^^^^^^^^^^
  File "/home/airflow/.local/lib/python3.12/site-packages/airflow/utils/session.py", line 97, in wrapper
    return func(*args, session=session, **kwargs)
           ^^^^^^^^^^^^^^^^^^^^^^^^^^^^^^^^^^^^^^
  File "/home/airflow/.local/lib/python3.12/site-packages/airflow/models/taskinstance.py", line 3005, in _run_raw_task
    return _run_raw_task(
           ^^^^^^^^^^^^^^
  File "/home/airflow/.local/lib/python3.12/site-packages/airflow/models/taskinstance.py", line 273, in _run_raw_task
    TaskInstance._execute_task_with_callbacks(
  File "/home/airflow/.local/lib/python3.12/site-packages/airflow/models/taskinstance.py", line 3159, in _execute_task_with_callbacks
    result = self._execute_task(context, task_orig)
             ^^^^^^^^^^^^^^^^^^^^^^^^^^^^^^^^^^^^^^
  File "/home/airflow/.local/lib/python3.12/site-packages/airflow/models/taskinstance.py", line 3183, in _execute_task
    return _execute_task(self, context, task_orig)
           ^^^^^^^^^^^^^^^^^^^^^^^^^^^^^^^^^^^^^^^
  File "/home/airflow/.local/lib/python3.12/site-packages/airflow/models/taskinstance.py", line 767, in _execute_task
    result = _execute_callable(context=context, **execute_callable_kwargs)
             ^^^^^^^^^^^^^^^^^^^^^^^^^^^^^^^^^^^^^^^^^^^^^^^^^^^^^^^^^^^^^
  File "/home/airflow/.local/lib/python3.12/site-packages/airflow/models/taskinstance.py", line 733, in _execute_callable
    return ExecutionCallableRunner(
           ^^^^^^^^^^^^^^^^^^^^^^^^
  File "/home/airflow/.local/lib/python3.12/site-packages/airflow/utils/operator_helpers.py", line 252, in run
    return self.func(*args, **kwargs)
           ^^^^^^^^^^^^^^^^^^^^^^^^^^
  File "/home/airflow/.local/lib/python3.12/site-packages/airflow/models/baseoperator.py", line 422, in wrapper
    return func(self, *args, **kwargs)
           ^^^^^^^^^^^^^^^^^^^^^^^^^^^
  File "/home/airflow/.local/lib/python3.12/site-packages/airflow/operators/python.py", line 238, in execute
    return_value = self.execute_callable()
                   ^^^^^^^^^^^^^^^^^^^^^^^
  File "/home/airflow/.local/lib/python3.12/site-packages/airflow/operators/python.py", line 256, in execute_callable
    return runner.run(*self.op_args, **self.op_kwargs)
           ^^^^^^^^^^^^^^^^^^^^^^^^^^^^^^^^^^^^^^^^^^^
  File "/home/airflow/.local/lib/python3.12/site-packages/airflow/utils/operator_helpers.py", line 252, in run
    return self.func(*args, **kwargs)
           ^^^^^^^^^^^^^^^^^^^^^^^^^^
  File "/opt/airflow/dags/postgre.py", line 13, in get_data
    cols=[desc[0] for desc in cursor.description()]
                              ^^^^^^^^^^^^^^^^^^^^
TypeError: 'tuple' object is not callable
[2025-01-20T13:00:44.808+0000] {local_task_job_runner.py:266} INFO - Task exited with return code 1
[2025-01-20T13:00:44.816+0000] {taskinstance.py:3895} INFO - 0 downstream tasks scheduled from follow-on schedule check
[2025-01-20T13:00:44.819+0000] {local_task_job_runner.py:245} INFO - ::endgroup::
